Traceback (most recent call last):
  File "/home/ubuntu/miniconda3/envs/sd/lib/python3.10/site-packages/transformers/utils/hub.py", line 403, in cached_file
    resolved_file = hf_hub_download(
  File "/home/ubuntu/miniconda3/envs/sd/lib/python3.10/site-packages/huggingface_hub/utils/_validators.py", line 106, in _inner_fn
    validate_repo_id(arg_value)
  File "/home/ubuntu/miniconda3/envs/sd/lib/python3.10/site-packages/huggingface_hub/utils/_validators.py", line 154, in validate_repo_id
    raise HFValidationError(
huggingface_hub.errors.HFValidationError: Repo id must be in the form 'repo_name' or 'namespace/repo_name': '../model_ckpt/vicuna-13b-v1.5'. Use `repo_type` argument if needed.

The above exception was the direct cause of the following exception:

Traceback (most recent call last):
  File "/home/ubuntu/sd/HandEval/test.py", line 226, in <module>
    main(args)
  File "/home/ubuntu/sd/HandEval/test.py", line 194, in main
    model = ModelClass(args.model_ckpt, **vars(args))
  File "/home/ubuntu/sd/HandEval/models/vicuna_wrapper.py", line 61, in __init__
    self.tokenizer = AutoTokenizer.from_pretrained(ckpt, revision=revision)
  File "/home/ubuntu/miniconda3/envs/sd/lib/python3.10/site-packages/transformers/models/auto/tokenization_auto.py", line 857, in from_pretrained
    tokenizer_config = get_tokenizer_config(pretrained_model_name_or_path, **kwargs)
  File "/home/ubuntu/miniconda3/envs/sd/lib/python3.10/site-packages/transformers/models/auto/tokenization_auto.py", line 689, in get_tokenizer_config
    resolved_config_file = cached_file(
  File "/home/ubuntu/miniconda3/envs/sd/lib/python3.10/site-packages/transformers/utils/hub.py", line 469, in cached_file
    raise EnvironmentError(
OSError: Incorrect path_or_model_id: '../model_ckpt/vicuna-13b-v1.5'. Please provide either the path to a local folder or the repo_id of a model on the Hub.
